<?xml version="1.0"?>
<robot xmlns:xacro="http://www.ros.org/wiki/xacro">

    <xacro:macro name="left_forward_wheel">

        <link name="Left_forward_wheel1">
            <inertial>
                <origin xyz="1.2490009027033E-16 -6.1409211049579E-16 -0.0318963397161268" rpy="0 0 0" />
                <mass value="0.38693434007123" />
                <inertia ixx="0.000164665684225832" ixy="1.03435021381098E-16" ixz="2.79933590586541E-16" iyy="0.000164665684225701" iyz="1.53586588595806E-16" izz="0.000205539151193427" />
            </inertial>
            <visual>
                <origin xyz="0 0 0" rpy="0 0 0" />
                <geometry>
                    <cylinder length="0.009" radius="0.014"/>
                </geometry>
                <material name="">
                    <color rgba="0.752941176470588 0.752941176470588 0.752941176470588 1" />
                </material>
            </visual>
            <collision>
                <origin xyz="0 0 0" rpy="0 0 0" />
                <geometry>
                    <cylinder length="0.009" radius="0.014"/>
                </geometry>
            </collision>
        </link>
        <joint name="Left_forward_joint1" type="continuous">
            <origin xyz="0.1135 0.165 -0.0179" rpy="-1.5708 0 0" />
            <parent link="base_link" />
            <child link="Left_forward_wheel1" />
            <axis xyz="0 0 1" />
            <dynamics damping="0.1" friction="0.1" />
        </joint>

    <gazebo reference="Left_forward_wheel1">
		<material>Gazebo/Green</material>
		<kp>1000000.0</kp> <!-- kp and kd for rubber -->
		<kd>100.0</kd>
		<mu1>1.0</mu1>
		<mu2>1.0</mu2>
		<maxVel>3.0</maxVel>
		<minDepth>0.00</minDepth>
	</gazebo>

      <gazebo>
    
    <plugin name="left_forward_wheel_controller" filename="libgazebo_ros_control.so">
      <updateRate>10.0</updateRate>
      <robotNamespace>/midterm</robotNamespace>
      <leftFrontJoint>Left_forward_joint1</leftFrontJoint>
      <wheelSeparation>0.4</wheelSeparation>
      <wheelDiameter>0.2</wheelDiameter>
      <robotBaseFrame>base_footprint</robotBaseFrame>
      <torque>10</torque>

      <topicName>cmd_vel</topicName>
      <odometryTopic>odom</odometryTopic>
      <odometryFrame>odom</odometryFrame>

      <commandTopic>cmd_vel</commandTopic>
      <topic_name_twist>cmd_vel</topic_name_twist>
      <topic_name_odometry>odom</topic_name_odometry>
      <topic_name_joint>joint</topic_name_joint>

      <broadcastTF>true</broadcastTF>

      <covariance_x>0.0001</covariance_x>
      <covariance_y>0.0001</covariance_y>
      <covariance_yaw>0.01</covariance_yaw>

    </plugin>

  </gazebo>

    </xacro:macro>

</robot>