<?xml version="1.0"?>
<robot xmlns:xacro="http://www.ros.org/wiki/xacro">

    <xacro:macro name="right_forward_wheel">

        <link name="Right_forward_wheel1">
            <inertial>
                <origin xyz="-1.2490009027033E-16 4.85722573273506E-17 -0.0318963396900528" rpy="0 0 0" />
                <mass value="0.386934339646562" />
                <inertia ixx="0.00016466568423101" ixy="-3.19541061769317E-17" ixz="-3.82361260302432E-17" iyy="0.000164665684231041" iyz="-2.40756939158418E-17" izz="0.000205539151181393" />
            </inertial>
            <visual>
                <origin xyz="0 0 0" rpy="0 0 0" />
                <geometry>
                    <cylinder length="0.009" radius="0.014"/>
                </geometry>
                <material name="">
                    <color rgba="0.752941176470588 0.752941176470588 0.752941176470588 1" />
                </material>
            </visual>
            <collision>
                <origin xyz="0 0 0" rpy="0 0 0" />
                <geometry>
                    <cylinder length="0.009" radius="0.014"/>
                </geometry>
            </collision>
        </link>
        <joint name="Right_forward_joint1" type="continuous">
            <origin xyz="0.1135 -0.165 -0.0179" rpy="1.5708 0 0" />
            <parent link="base_link" />
            <child link="Right_forward_wheel1" />
            <axis xyz="0 0 -1" />
            <dynamics damping="0.1" friction="0.1" />
        </joint>

	<gazebo reference="Right_forward_wheel1">
		<material>Gazebo/Green</material>
		<kp>1000000.0</kp> <!-- kp and kd for rubber -->
		<kd>100.0</kd>
		<mu1>1.0</mu1>
		<mu2>1.0</mu2>
		<maxVel>3.0</maxVel>
		<minDepth>0.00</minDepth>
	</gazebo>


      <gazebo>
    
    <plugin name="right_forward_wheel_controller" filename="libgazebo_ros_control.so">
      <updateRate>10.0</updateRate>
      <robotNamespace>/midterm</robotNamespace>
      <rightFrontJoint>Right_forward_joint1</rightFrontJoint>
      <wheelSeparation>0.4</wheelSeparation>
      <wheelDiameter>0.2</wheelDiameter>
      <robotBaseFrame>base_footprint</robotBaseFrame>
      <torque>10</torque>

      <topicName>cmd_vel</topicName>
      <odometryTopic>odom</odometryTopic>
      <odometryFrame>odom</odometryFrame>

      <commandTopic>cmd_vel</commandTopic>
      <topic_name_twist>cmd_vel</topic_name_twist>
      <topic_name_odometry>odom</topic_name_odometry>
      <topic_name_joint>joint</topic_name_joint>

      <broadcastTF>true</broadcastTF>

      <covariance_x>0.0001</covariance_x>
      <covariance_y>0.0001</covariance_y>
      <covariance_yaw>0.01</covariance_yaw>

    </plugin>

  </gazebo>

    </xacro:macro>

</robot>