<?xml version="1.0"?>
<robot xmlns:xacro="http://www.ros.org/wiki/xacro">

    <xacro:macro name="right_backward_wheel">

        <link name="Right_backward_wheel1">
            <inertial>
                <origin xyz="3.88578058618805E-16 3.81639164714898E-17 -0.0318963396918449" rpy="0 0 0" />
                <mass value="0.386934339673269" />
                <inertia ixx="0.000164665684230379" ixy="7.84436153661023E-17" ixz="-5.11751895742631E-17" iyy="0.000164665684230335" iyz="-1.24644074562022E-17" izz="0.000205539151179241" />
            </inertial>
            <visual>
                <origin xyz="0 0 0" rpy="0 0 0" />
                <geometry>
                    <cylinder length="0.009" radius="0.014"/>
                </geometry>
                <material name="">
                    <color rgba="0.752941176470588 0.752941176470588 0.752941176470588 1" />
                </material>
            </visual>
            <collision>
                <origin xyz="0 0 0" rpy="0 0 0" />
                <geometry>
                    <cylinder length="0.009" radius="0.014"/>
                </geometry>
            </collision>
        </link>
        <joint name="Right_backward_joint1" type="continuous">
            <origin xyz="-0.1135 -0.165 -0.0179" rpy="1.5708 0 0" />
            <parent link="base_link" />
            <child link="Right_backward_wheel1" />
            <axis xyz="0 0 -1" />
            <dynamics damping="0.1" friction="0.1" />
        </joint>

	<gazebo reference="Right_backward_wheel1">
		<material>Gazebo/Green</material>
		<kp>1000000.0</kp> <!-- kp and kd for rubber -->
		<kd>100.0</kd>
		<mu1>1.0</mu1>
		<mu2>1.0</mu2>
		<maxVel>3.0</maxVel>
		<minDepth>0.00</minDepth>
	</gazebo>

      <gazebo>
    
    <plugin name="right_backward_wheel_controller" filename="libgazebo_ros_control.so">
      <updateRate>10.0</updateRate>
      <robotNamespace>/midterm</robotNamespace>
      <rightRearJoint>Right_backward_joint1</rightRearJoint>
      <wheelSeparation>0.4</wheelSeparation>
      <wheelDiameter>0.2</wheelDiameter>
      <robotBaseFrame>base_footprint</robotBaseFrame>
      <torque>10</torque>

      <topicName>cmd_vel</topicName>
      <odometryTopic>odom</odometryTopic>
      <odometryFrame>odom</odometryFrame>

      <commandTopic>cmd_vel</commandTopic>
      <topic_name_twist>cmd_vel</topic_name_twist>
      <topic_name_odometry>odom</topic_name_odometry>
      <topic_name_joint>joint</topic_name_joint>

      <broadcastTF>true</broadcastTF>

      <covariance_x>0.0001</covariance_x>
      <covariance_y>0.0001</covariance_y>
      <covariance_yaw>0.01</covariance_yaw>

    </plugin>

  </gazebo>

    </xacro:macro>

</robot>