<?xml version="1.0"?>
<robot xmlns:xacro="http://www.ros.org/wiki/xacro">

    <xacro:macro name="wheel1">

        <link name="Left_forward_wheel1">
            <inertial>
                <origin xyz="1.2490009027033E-16 -6.1409211049579E-16 -0.0318963397161268" rpy="0 0 0" />
                <mass value="0.38693434007123" />
                <inertia ixx="0.000164665684225832" ixy="1.03435021381098E-16" ixz="2.79933590586541E-16" iyy="0.000164665684225701" iyz="1.53586588595806E-16" izz="0.000205539151193427" />
            </inertial>
            <visual>
                <origin xyz="0 0 0" rpy="0 0 0" />
                <geometry>
                    <cylinder length="0.009" radius="0.014"/>
                </geometry>
                <material name="">
                    <color rgba="0.752941176470588 0.752941176470588 0.752941176470588 1" />
                </material>
            </visual>
            <collision>
                <origin xyz="0 0 0" rpy="0 0 0" />
                <geometry>
                    <cylinder length="0.009" radius="0.014"/>
                </geometry>
            </collision>
        </link>
        <joint name="Left_forward_joint1" type="continuous">
            <origin xyz="0.1135 0.165 -0.0179" rpy="-1.5708 0 0" />
            <parent link="base_link" />
            <child link="Left_forward_wheel1" />
            <axis xyz="0 0 1" />
            <dynamics damping="0.1" friction="0.1" />
        </joint>



        <link name="Right_forward_wheel1">
            <inertial>
                <origin xyz="-1.2490009027033E-16 4.85722573273506E-17 -0.0318963396900528" rpy="0 0 0" />
                <mass value="0.386934339646562" />
                <inertia ixx="0.00016466568423101" ixy="-3.19541061769317E-17" ixz="-3.82361260302432E-17" iyy="0.000164665684231041" iyz="-2.40756939158418E-17" izz="0.000205539151181393" />
            </inertial>
            <visual>
                <origin xyz="0 0 0" rpy="0 0 0" />
                <geometry>
                    <cylinder length="0.009" radius="0.014"/>
                </geometry>
                <material name="">
                    <color rgba="0.752941176470588 0.752941176470588 0.752941176470588 1" />
                </material>
            </visual>
            <collision>
                <origin xyz="0 0 0" rpy="0 0 0" />
                <geometry>
                    <cylinder length="0.009" radius="0.014"/>
                </geometry>
            </collision>
        </link>
        <joint name="Right_forward_joint1" type="continuous">
            <origin xyz="0.1135 -0.165 -0.0179" rpy="1.5708 0 0" />
            <parent link="base_link" />
            <child link="Right_forward_wheel1" />
            <axis xyz="0 0 -1" />
            <dynamics damping="0.1" friction="0.1" />
        </joint>



        <link name="Left_backward_wheel1">
            <inertial>
                <origin xyz="-3.88578058618805E-16 1.52655665885959E-16 -0.0318963396983103" rpy="0 0 0" />
                <mass value="0.38693433977405" />
                <inertia ixx="0.000164665684224543" ixy="-5.44366971754961E-17" ixz="-1.64638873428518E-17" iyy="0.000164665684224467" iyz="-4.73291942910437E-17" izz="0.000205539151192063" />
            </inertial>
            <visual>
                <origin xyz="0 0 0" rpy="0 0 0" />
                <geometry>
                    <cylinder length="0.009" radius="0.014"/>
                </geometry>
                <material name="">
                    <color rgba="0.752941176470588 0.752941176470588 0.752941176470588 1" />
                </material>
            </visual>
            <collision>
                <origin xyz="0 0 0" rpy="0 0 0" />
                <geometry>
                    <cylinder length="0.009" radius="0.014"/>
                </geometry>
            </collision>
        </link>
        <joint name="Left_backward_joint1" type="continuous">
            <origin xyz="-0.1135 0.165 -0.0179" rpy="-1.5708 0 0" />
            <parent link="base_link" />
            <child link="Left_backward_wheel1" />
            <axis xyz="0 0 1" />
            <dynamics damping="0.1" friction="0.1" />
        </joint>


        <link name="Right_backward_wheel1">
            <inertial>
                <origin xyz="3.88578058618805E-16 3.81639164714898E-17 -0.0318963396918449" rpy="0 0 0" />
                <mass value="0.386934339673269" />
                <inertia ixx="0.000164665684230379" ixy="7.84436153661023E-17" ixz="-5.11751895742631E-17" iyy="0.000164665684230335" iyz="-1.24644074562022E-17" izz="0.000205539151179241" />
            </inertial>
            <visual>
                <origin xyz="0 0 0" rpy="0 0 0" />
                <geometry>
                    <cylinder length="0.009" radius="0.014"/>
                </geometry>
                <material name="">
                    <color rgba="0.752941176470588 0.752941176470588 0.752941176470588 1" />
                </material>
            </visual>
            <collision>
                <origin xyz="0 0 0" rpy="0 0 0" />
                <geometry>
                    <cylinder length="0.009" radius="0.014"/>
                </geometry>
            </collision>
        </link>
        <joint name="Right_backward_joint1" type="continuous">
            <origin xyz="-0.1135 -0.165 -0.0179" rpy="1.5708 0 0" />
            <parent link="base_link" />
            <child link="Right_backward_wheel1" />
            <axis xyz="0 0 -1" />
            <dynamics damping="0.1" friction="0.1" />
        </joint>

    <gazebo reference="Left_forward_wheel1">
		<material>Gazebo/Green</material>
		<kp>1000000.0</kp> <!-- kp and kd for rubber -->
		<kd>100.0</kd>
		<mu1>1.0</mu1>
		<mu2>1.0</mu2>
		<maxVel>3.0</maxVel>
		<minDepth>0.00</minDepth>
	</gazebo>

	<gazebo reference="Left_backward_wheel1">
		<material>Gazebo/Green</material>
		<kp>1000000.0</kp> <!-- kp and kd for rubber -->
		<kd>100.0</kd>
		<mu1>1.0</mu1>
		<mu2>1.0</mu2>
		<maxVel>3.0</maxVel>
		<minDepth>0.00</minDepth>
	</gazebo>

	<gazebo reference="Right_forward_wheel1">
		<material>Gazebo/Green</material>
		<kp>1000000.0</kp> <!-- kp and kd for rubber -->
		<kd>100.0</kd>
		<mu1>1.0</mu1>
		<mu2>1.0</mu2>
		<maxVel>3.0</maxVel>
		<minDepth>0.00</minDepth>
	</gazebo>

	<gazebo reference="Right_backward_wheel1">
		<material>Gazebo/Green</material>
		<kp>1000000.0</kp> <!-- kp and kd for rubber -->
		<kd>100.0</kd>
		<mu1>1.0</mu1>
		<mu2>1.0</mu2>
		<maxVel>3.0</maxVel>
		<minDepth>0.00</minDepth>
	</gazebo>

      <gazebo>
    
    <plugin name="skid_steer_drive_controller" filename="libgazebo_ros_skid_steer_drive.so">
      <updateRate>10.0</updateRate>
      <robotNamespace>/midterm</robotNamespace>
      <leftFrontJoint>Left_forward_joint1</leftFrontJoint>
      <rightFrontJoint>Right_forward_joint1</rightFrontJoint>
      <leftRearJoint>Left_backward_joint1</leftRearJoint>
      <rightRearJoint>Right_backward_joint1</rightRearJoint>
      <wheelSeparation>0.4</wheelSeparation>
      <wheelDiameter>0.2</wheelDiameter>
      <robotBaseFrame>base_footprint</robotBaseFrame>
      <torque>10</torque>

      <topicName>cmd_vel</topicName>
      <odometryTopic>odom</odometryTopic>
      <odometryFrame>odom</odometryFrame>

      <commandTopic>cmd_vel</commandTopic>
      <topic_name_twist>cmd_vel</topic_name_twist>
      <topic_name_odometry>odom</topic_name_odometry>
      <topic_name_joint>joint</topic_name_joint>

      <broadcastTF>true</broadcastTF>

      <covariance_x>0.0001</covariance_x>
      <covariance_y>0.0001</covariance_y>
      <covariance_yaw>0.01</covariance_yaw>

    </plugin>

  </gazebo>

    </xacro:macro>

</robot>