<?xml version="1.0" encoding="utf-8"?>
<!-- This URDF was automatically created by SolidWorks to URDF Exporter! Originally created by Stephen Brawner (brawner@gmail.com) 
     Commit Version: 1.6.0-4-g7f85cfe  Build Version: 1.6.7995.38578
     For more information, please see http://wiki.ros.org/sw_urdf_exporter -->
<robot
  name="urdf">
  <link
    name="base_link">
    <inertial>
      <origin
        xyz="-0.00280638761136618 9.22799255059434E-05 -0.00823780680525314"
        rpy="0 0 0" />
      <mass
        value="2.73624245548653" />
      <inertia
        ixx="0.0111853471576075"
        ixy="-7.2511498712482E-11"
        ixz="0.000255799746468985"
        iyy="0.0161314353661535"
        iyz="1.81571166508761E-07"
        izz="0.0239017300755925" />
    </inertial>
    <visual>
      <origin
        xyz="0 0 0"
        rpy="0 0 0" />
      <geometry>
        <mesh
          filename="package://midterm/urdf/meshes/base_link.STL" />
      </geometry>
      <material
        name="">
        <color
          rgba="0.792156862745098 0.819607843137255 0.933333333333333 1" />
      </material>
    </visual>
    <collision>
      <origin
        xyz="0 0 0"
        rpy="0 0 0" />
      <geometry>
        <mesh
          filename="package://midterm/urdf/meshes/base_link.STL" />
      </geometry>
    </collision>
  </link>
  <link
    name="Left_forward_wheel">
    <inertial>
      <origin
        xyz="1.2490009027033E-16 -6.1409211049579E-16 -0.0318963397161268"
        rpy="0 0 0" />
      <mass
        value="0.38693434007123" />
      <inertia
        ixx="0.000164665684225832"
        ixy="1.03435021381098E-16"
        ixz="2.79933590586541E-16"
        iyy="0.000164665684225701"
        iyz="1.53586588595806E-16"
        izz="0.000205539151193427" />
    </inertial>
    <visual>
      <origin
        xyz="0 0 0"
        rpy="0 0 0" />
      <geometry>
        <mesh
          filename="package://midterm/urdf/meshes/Left_forward_wheel.STL" />
      </geometry>
      <material
        name="">
        <color
          rgba="0.752941176470588 0.752941176470588 0.752941176470588 1" />
      </material>
    </visual>
    <collision>
      <origin
        xyz="0 0 0"
        rpy="0 0 0" />
      <geometry>
        <mesh
          filename="package://midterm/urdf/meshes/Left_forward_wheel.STL" />
      </geometry>
    </collision>
  </link>
  <joint
    name="Left_forward_joint"
    type="continuous">
    <origin
      xyz="0.1135 0.165 -0.0179"
      rpy="-1.5708 0 0" />
    <parent
      link="base_link" />
    <child
      link="Left_forward_wheel" />
    <axis
      xyz="0 0 1" />
    <dynamics
      damping="0.1"
      friction="0.1" />
  </joint>
  <link
    name="Right_forward_wheel">
    <inertial>
      <origin
        xyz="-1.2490009027033E-16 4.85722573273506E-17 -0.0318963396900528"
        rpy="0 0 0" />
      <mass
        value="0.386934339646562" />
      <inertia
        ixx="0.00016466568423101"
        ixy="-3.19541061769317E-17"
        ixz="-3.82361260302432E-17"
        iyy="0.000164665684231041"
        iyz="-2.40756939158418E-17"
        izz="0.000205539151181393" />
    </inertial>
    <visual>
      <origin
        xyz="0 0 0"
        rpy="0 0 0" />
      <geometry>
        <mesh
          filename="package://midterm/urdf/meshes/Right_forward_wheel.STL" />
      </geometry>
      <material
        name="">
        <color
          rgba="0.752941176470588 0.752941176470588 0.752941176470588 1" />
      </material>
    </visual>
    <collision>
      <origin
        xyz="0 0 0"
        rpy="0 0 0" />
      <geometry>
        <mesh
          filename="package://midterm/urdf/meshes/Right_forward_wheel.STL" />
      </geometry>
    </collision>
  </link>
  <joint
    name="Right_forward_joint"
    type="continuous">
    <origin
      xyz="0.1135 -0.165 -0.0179"
      rpy="1.5708 0 0" />
    <parent
      link="base_link" />
    <child
      link="Right_forward_wheel" />
    <axis
      xyz="0 0 1" />
    <dynamics
      damping="0.1"
      friction="0.1" />
  </joint>
  <link
    name="Left_backward_wheel">
    <inertial>
      <origin
        xyz="-3.88578058618805E-16 1.52655665885959E-16 -0.0318963396983103"
        rpy="0 0 0" />
      <mass
        value="0.38693433977405" />
      <inertia
        ixx="0.000164665684224543"
        ixy="-5.44366971754961E-17"
        ixz="-1.64638873428518E-17"
        iyy="0.000164665684224467"
        iyz="-4.73291942910437E-17"
        izz="0.000205539151192063" />
    </inertial>
    <visual>
      <origin
        xyz="0 0 0"
        rpy="0 0 0" />
      <geometry>
        <mesh
          filename="package://midterm/urdf/meshes/Left_backward_wheel.STL" />
      </geometry>
      <material
        name="">
        <color
          rgba="0.752941176470588 0.752941176470588 0.752941176470588 1" />
      </material>
    </visual>
    <collision>
      <origin
        xyz="0 0 0"
        rpy="0 0 0" />
      <geometry>
        <mesh
          filename="package://midterm/urdf/meshes/Left_backward_wheel.STL" />
      </geometry>
    </collision>
  </link>
  <joint
    name="Left_backward_joint"
    type="continuous">
    <origin
      xyz="-0.1135 0.165 -0.0179"
      rpy="-1.5708 0 0" />
    <parent
      link="base_link" />
    <child
      link="Left_backward_wheel" />
    <axis
      xyz="0 0 1" />
    <dynamics
      damping="0.1"
      friction="0.1" />
  </joint>
  <link
    name="Right_backward_wheel">
    <inertial>
      <origin
        xyz="3.88578058618805E-16 3.81639164714898E-17 -0.0318963396918449"
        rpy="0 0 0" />
      <mass
        value="0.386934339673269" />
      <inertia
        ixx="0.000164665684230379"
        ixy="7.84436153661023E-17"
        ixz="-5.11751895742631E-17"
        iyy="0.000164665684230335"
        iyz="-1.24644074562022E-17"
        izz="0.000205539151179241" />
    </inertial>
    <visual>
      <origin
        xyz="0 0 0"
        rpy="0 0 0" />
      <geometry>
        <mesh
          filename="package://midterm/urdf/meshes/Right_backward_wheel.STL" />
      </geometry>
      <material
        name="">
        <color
          rgba="0.752941176470588 0.752941176470588 0.752941176470588 1" />
      </material>
    </visual>
    <collision>
      <origin
        xyz="0 0 0"
        rpy="0 0 0" />
      <geometry>
        <mesh
          filename="package://midterm/urdf/meshes/Right_backward_wheel.STL" />
      </geometry>
    </collision>
  </link>
  <joint
    name="Right_backward_joint"
    type="continuous">
    <origin
      xyz="-0.1135 -0.165 -0.0179"
      rpy="1.5708 0 0" />
    <parent
      link="base_link" />
    <child
      link="Right_backward_wheel" />
    <axis
      xyz="0 0 1" />
    <dynamics
      damping="0.1"
      friction="0.1" />
  </joint>
  <link
    name="lindar">
    <inertial>
      <origin
        xyz="-0.00829409957033964 -6.93889390390723E-18 0.010701142222791"
        rpy="0 0 0" />
      <mass
        value="0.146695752131392" />
      <inertia
        ixx="6.22721120792818E-05"
        ixy="-1.8353446398283E-20"
        ixz="-1.88658076337422E-05"
        iyy="0.000109673997590948"
        iyz="-8.39148657969651E-21"
        izz="0.000125682524275729" />
    </inertial>
    <visual>
      <origin
        xyz="0 0 0"
        rpy="0 0 0" />
      <geometry>
        <mesh
          filename="package://midterm/urdf/meshes/lindar.STL" />
      </geometry>
      <material
        name="">
        <color
          rgba="0.792156862745098 0.819607843137255 0.933333333333333 1" />
      </material>
    </visual>
    <collision>
      <origin
        xyz="0 0 0"
        rpy="0 0 0" />
      <geometry>
        <mesh
          filename="package://midterm/urdf/meshes/lindar.STL" />
      </geometry>
    </collision>
  </link>
  <joint
    name="lidar_joint"
    type="fixed">
    <origin
      xyz="0.108 0 0.042"
      rpy="0 0 0" />
    <parent
      link="base_link" />
    <child
      link="lindar" />
    <axis
      xyz="0 0 0" />
    <dynamics
      damping="0.1"
      friction="0.1" />
  </joint>
  <link
    name="camera">
    <inertial>
      <origin
        xyz="0.00496941747572817 0.00663466659504938 0.00325439033106007"
        rpy="0 0 0" />
      <mass
        value="0.00339776560761352" />
      <inertia
        ixx="2.0587228463327E-07"
        ixy="-1.65206280027943E-23"
        ixz="5.15967188711596E-23"
        iyy="1.83317693669082E-07"
        iyz="3.02855427268585E-08"
        izz="1.84150046477411E-07" />
    </inertial>
    <visual>
      <origin
        xyz="0 0 0"
        rpy="0 0 0" />
      <geometry>
        <mesh
          filename="package://midterm/urdf/meshes/camera.STL" />
      </geometry>
      <material
        name="">
        <color
          rgba="0.792156862745098 0.819607843137255 0.933333333333333 1" />
      </material>
    </visual>
    <collision>
      <origin
        xyz="0 0 0"
        rpy="0 0 0" />
      <geometry>
        <mesh
          filename="package://midterm/urdf/meshes/camera.STL" />
      </geometry>
    </collision>
  </link>
  <joint
    name="camera_joint"
    type="fixed">
    <origin
      xyz="0.15 -0.0049694 -0.011361"
      rpy="3.1416 0 1.5708" />
    <parent
      link="base_link" />
    <child
      link="camera" />
    <axis
      xyz="0 0 0" />
    <dynamics
      damping="0.1"
      friction="0.1" />
  </joint>
  <link
    name="link1">
    <inertial>
      <origin
        xyz="0.0130133047131633 0.0889204179261883 -0.0296765696165617"
        rpy="0 0 0" />
      <mass
        value="0.164486554024359" />
      <inertia
        ixx="0.000544779739701674"
        ixy="-7.45784439965975E-05"
        ixz="9.94065100983671E-08"
        iyy="4.6096716851494E-05"
        iyz="6.79248063491979E-07"
        izz="0.000565982592073471" />
    </inertial>
    <visual>
      <origin
        xyz="0 0 0"
        rpy="0 0 0" />
      <geometry>
        <mesh
          filename="package://midterm/urdf/meshes/link1.STL" />
      </geometry>
      <material
        name="">
        <color
          rgba="0.792156862745098 0.819607843137255 0.933333333333333 1" />
      </material>
    </visual>
    <collision>
      <origin
        xyz="0 0 0"
        rpy="0 0 0" />
      <geometry>
        <mesh
          filename="package://midterm/urdf/meshes/link1.STL" />
      </geometry>
    </collision>
  </link>
  <joint
    name="link1_joint"
    type="revolute">
    <origin
      xyz="-0.025 0.0295 0.085"
      rpy="1.5708 -0.85308 3.1416" />
    <parent
      link="base_link" />
    <child
      link="link1" />
    <axis
      xyz="0 0 1" />
    <limit
      lower="0"
      upper="0"
      effort="0"
      velocity="0" />
    <dynamics
      damping="0.1"
      friction="0.1" />
  </joint>
  <link
    name="link2">
    <inertial>
      <origin
        xyz="0.104899329069202 0.0379645740880208 -0.0321285668568063"
        rpy="0 0 0" />
      <mass
        value="0.184332677556066" />
      <inertia
        ixx="0.000107535031720432"
        ixy="-0.000205718924701572"
        ixz="-1.78149467639473E-06"
        iyy="0.000593870869716796"
        iyz="-6.41437127577083E-07"
        izz="0.000681305864636033" />
    </inertial>
    <visual>
      <origin
        xyz="0 0 0"
        rpy="0 0 0" />
      <geometry>
        <mesh
          filename="package://midterm/urdf/meshes/link2.STL" />
      </geometry>
      <material
        name="">
        <color
          rgba="0.792156862745098 0.819607843137255 0.933333333333333 1" />
      </material>
    </visual>
    <collision>
      <origin
        xyz="0 0 0"
        rpy="0 0 0" />
      <geometry>
        <mesh
          filename="package://midterm/urdf/meshes/link2.STL" />
      </geometry>
    </collision>
  </link>
  <joint
    name="link2_joint"
    type="revolute">
    <origin
      xyz="0.024617 0.16821 -0.08085"
      rpy="3.1416 0 2.2885" />
    <parent
      link="link1" />
    <child
      link="link2" />
    <axis
      xyz="0 0 1" />
    <limit
      lower="0"
      upper="0"
      effort="0"
      velocity="0" />
    <dynamics
      damping="0.1"
      friction="0.1" />
  </joint>
</robot>
